Workbook

Sheet SOC 1
A1: Año | B1: DESELECTRIFICACION | I1: %
C2: Costa Rica | D2: El Salvador | E2: Guatemala | F2: Honduras | G2: Nicaragua | H2: Panamá | I2: TOTAL
A3: 2024 | B3: 100 | C3: 0.6 | D3: 1.7 | E3: 9.11 | F3: 13.64 | G3: 0.443 | H3: 4 | I3: 29.493
A4: 2023 | C4: 0.6 | D4: 1.7 | E4: 9.61 | F4: 13.72 | G4: 0.59 | H4: 4.4 | I4: 30.62
A5: 2022 | C5: 0.6 | D5: 1.8 | E5: 10.06 | F5: 14.37 | G5: 0.74 | H5: 4.8 | I5: 32.37
A6: 2021 | C6: 0.6 | D6: 2.1 | E6: 10.74 | F6: 14.23 | G6: 0.91 | H6: 5.1 | I6: 33.68
A7: 2020 | C7: 0.6 | D7: 2.2 | E7: 10.1 | F7: 14.78 | G7: 1.5 | H7: 5.6 | I7: 34.78

Sheet SOC 2 NIC  (2)
B1: Año | C1: % de reajuste salarial en Nicaragua | E1: Ingresos
B2: 2024 | C2: 10.1 | E2: Salario | F2: No pobres | G2: 29% más pobres | I2: Año | J2: % Incremento | K2: Salario anual con Ajuste NP | L2: Salario anual con Ajuste 29+ pobres
B3: 2023 | C3: 10 | E3: Agricola | F3: 1894.8 | G3: 3904.6 | I3: 2014 | J3: 10.27 | K3: 44870.25 | L3: 17148.55
B4: 2022 | C4: 7 | E4: no agricola | F4: 17654.1 | G4: 5960 | I4: 2015 | J4: 10.75 | K4: =(K3*J4/100)+K3 -> 49693.802 | L4: =(L3*J4/100)+L3 -> 18992.019
B5: 2021 | C5: 3 | E5: cuenta propia | I5: 2016 | J5: 9 | K5: =(K4*J5/100)+K4 -> 54166.244 | L5: =(L4*J5/100)+L4 -> 20701.301
B6: 2020 | C6: 2.63 | E6: Agricola | F6: 4318 | G6: 2577.25 | I6: 2017 | J6: 8.25 | K6: =(K5*J6/100)+K5 -> 58634.959 | L6: =(L5*J6/100)+L5 -> 22409.158
B7: 2019 | C7: 5.2 | E7: no agricola | F7: 12029.3 | G7: 1277 | I7: 2018 | J7: 5.2 | K7: =(K6*J7/100)+K6 -> 61683.977 | L7: =(L6*J7/100)+L6 -> 23574.434
B8: 2018 | C8: 5.2 | E8: PROMEDIO | F8: =AVERAGE(F3:F7) -> 8974.05 | G8: =AVERAGE(G3:G7) -> 3429.7125 | I8: 2019 | J8: 5.2 | K8: =(K7*J8/100)+K7 -> 64891.544 | L8: =(L7*J8/100)+L7 -> 24800.305
B9: 2017 | C9: 8.25 | I9: 2020 | J9: 2.63 | K9: =(K8*J9/100)+K8 -> 66598.191 | L9: =(L8*J9/100)+L8 -> 25452.553
B10: 2016 | C10: 9 | I10: 2021 | J10: 3 | K10: =(K9*J10/100)+K9 -> 68596.137 | L10: =(L9*J10/100)+L9 -> 26216.13
B11: 2015 | C11: 10.75 | I11: 2022 | J11: 7 | K11: =(K10*J11/100)+K10 -> 73397.867 | L11: =(L10*J11/100)+L10 -> 28051.259
B12: 2014 | C12: 10.27 | I12: 2023 | J12: 10 | K12: =(K11*J12/100)+K11 -> 80737.653 | L12: =(L11*J12/100)+L11 -> 30856.385
I13: 2024 | J13: 10.1 | K13: =(K12*J13/100)+K12 -> 88892.156 | L13: =(L12*J13/100)+L12 -> 33972.879
A17: AÑO | B17: DICIEMBRE | C17: Ingreso total (cord) | D17: cargo medio | E17: Salario anual NP | F17: Salario anual 29+P | G17: % Ingreso destinado al pago de electricidad Np | H17: % Ingreso destinado al pago de electricidad 29+P
A18: 2024 | D18: =_xlfn.FORECAST.LINEAR(A18,D19:D23,A19:A23) -> 4724.0907 | E18: =K13 -> 88892.156 | F18: =L13 -> 33972.879 | G18: =(D18/E18)*100 -> 5.3144067 | H18: =(D18/F18)*100 -> 13.905476
A19: 2023 | D19: =_xlfn.FORECAST.LINEAR(A19,D20:D23,A20:A23) -> 4913.1006 | E19: =K12 -> 80737.653 | F19: =L12 -> 30856.385 | G19: =(D19/E19)*100 -> 6.0852655 | H19: =(D19/F19)*100 -> 15.922476
A20: 2022 | B20: 1225848 | C20: 6.3716477e+09 | D20: =C20/B20 -> 5197.7469 | E20: =K11 -> 73397.867 | F20: =L11 -> 28051.259 | G20: =(D20/E20)*100 -> 7.0816049 | H20: =(D20/F20)*100 -> 18.529461
A21: 2021 | B21: 1209264 | C21: 6.0305436e+09 | D21: =C21/B21 -> 4986.9537 | E21: =K10 -> 68596.137 | F21: =L10 -> 26216.13 | G21: =(D21/E21)*100 -> 7.2700212 | H21: =(D21/F21)*100 -> 19.022464
A22: 2020 | B22: 1155606 | C22: 6.7043098e+09 | D22: =C22/B22 -> 5801.5533 | E22: =K9 -> 66598.191 | F22: =L9 -> 25452.553 | G22: =(D22/E22)*100 -> 8.7112776 | H22: =(D22/F22)*100 -> 22.793601
A23: 2019 | B23: 1130580 | C23: 6.2817811e+09 | D23: =C23/B23 -> 5556.2465 | E23: =K8 -> 64891.544 | F23: =L8 -> 24800.305 | G23: =(D23/E23)*100 -> 8.5623583 | H23: =(D23/F23)*100 -> 22.403944
E25: =E18/F18 -> 2.6165623

Sheet SOC 2 TOTAL
A1: % DE INGRESOS DESTINADOS AL PAGO DE ENERGIA ELECTRICA PROMEDIO
A2: Año | B2: NIC | C2: CR | D2: HD | E2: ES | F2: GUA | G2: PAN | H2: TOTAL
A3: 2024 | B3: ='SOC 2 NIC (2)'!G18 -> 5.3144067 | C3: ='SOC 2 CR'!E21 -> 1.8853931 | D3: ='SOC 2 HD'!E13 -> 6.5519766 | E3: ='SOC 2 ES'!J11 -> 1.7594525 | F3: ='SOC 2 GUA'!G17 -> 2.3814961 | G3: ='SOC 2 PAN'!I18 -> 2.7881558 | H3: =AVERAGE(B3:G3) -> 3.4468135
A4: 2023 | B4: ='SOC 2 NIC (2)'!G19 -> 6.0852655 | C4: ='SOC 2 CR'!E22 -> 1.8263095 | D4: ='SOC 2 HD'!E14 -> 6.2977619 | E4: ='SOC 2 ES'!J12 -> 1.7287699 | F4: ='SOC 2 GUA'!G18 -> 2.3675879 | G4: ='SOC 2 PAN'!I19 -> 2.5202873 | H4: =AVERAGE(B4:G4) -> 3.470997
A5: 2022 | B5: ='SOC 2 NIC (2)'!G20 -> 7.0816049 | C5: ='SOC 2 CR'!E23 -> 1.804922 | D5: ='SOC 2 HD'!E15 -> 5.8847582 | E5: ='SOC 2 ES'!J13 -> 1.8650332 | F5: ='SOC 2 GUA'!G19 -> 2.3463558 | G5: ='SOC 2 PAN'!I20 -> 2.5818742 | H5: =AVERAGE(B5:G5) -> 3.5940914
A6: 2021 | B6: ='SOC 2 NIC (2)'!G21 -> 7.2700212 | C6: ='SOC 2 CR'!E24 -> 1.8766132 | D6: ='SOC 2 HD'!E16 -> 5.1380738 | E6: ='SOC 2 ES'!J14 -> 2.0311657 | F6: ='SOC 2 GUA'!G20 -> 2.3851525 | G6: ='SOC 2 PAN'!I21 -> 2.4101295 | H6: =AVERAGE(B6:G6) -> 3.518526
A7: 2020 | B7: ='SOC 2 NIC (2)'!G22 -> 8.7112776 | C7: ='SOC 2 CR'!E25 -> 2.4081282 | D7: ='SOC 2 HD'!E17 -> 5.0996013 | E7: ='SOC 2 ES'!J15 -> 2.0633089 | F7: ='SOC 2 GUA'!G21 -> 2.3434942 | G7: ='SOC 2 PAN'!I22 -> 2.5991828 | H7: =AVERAGE(B7:G7) -> 3.8708322
A10: % DE INGRESOS DESTINADOS AL PAGO DE ENERGIA ELECTRICA 20%+P
A11: Año | B11: NIC | C11: CR | D11: HD | E11: ES | F11: GUA | G11: PAN | H11: TOTAL
A12: 2024 | B12: ='SOC 2 NIC (2)'!H18 -> 13.905476 | C12: ='SOC 2 CR'!F21 -> 13.971497 | D12: ='SOC 2 HD'!F13 -> 73.49463 | E12: ='SOC 2 ES'!K11 -> 7.2345368 | F12: ='SOC 2 GUA'!H17 -> 8.7879146 | G12: ='SOC 2 PAN'!J18 -> 30.986549 | H12: =AVERAGE(B12:G12) -> 24.7301
A13: 2023 | B13: ='SOC 2 NIC (2)'!H19 -> 15.922476 | C13: ='SOC 2 CR'!F22 -> 15.34537 | D13: ='SOC 2 HD'!F14 -> 65.870335 | E13: ='SOC 2 ES'!K12 -> 6.9145188 | F13: ='SOC 2 GUA'!H18 -> 8.7365922 | G13: ='SOC 2 PAN'!J19 -> 25.622921 | H13: =AVERAGE(B13:G13) -> 23.068702
A14: 2022 | B14: ='SOC 2 NIC (2)'!H20 -> 18.529461 | C14: ='SOC 2 CR'!F23 -> 14.822262 | D14: ='SOC 2 HD'!F15 -> 61.732542 | E14: ='SOC 2 ES'!K13 -> 7.0087598 | F14: ='SOC 2 GUA'!H19 -> 8.6582441 | G14: ='SOC 2 PAN'!J20 -> 28.694011 | H14: =AVERAGE(B14:G14) -> 23.24088
A15: 2021 | B15: ='SOC 2 NIC (2)'!H21 -> 19.022464 | C15: ='SOC 2 CR'!F24 -> 15.749043 | D15: ='SOC 2 HD'!F16 -> 51.343162 | E15: ='SOC 2 ES'!K14 -> 7.5546241 | F15: ='SOC 2 GUA'!H20 -> 8.8014069 | G15: ='SOC 2 PAN'!J21 -> 28.089485 | H15: =AVERAGE(B15:G15) -> 21.760031
A16: 2020 | B16: ='SOC 2 NIC (2)'!H22 -> 22.793601 | C16: ='SOC 2 CR'!F25 -> 21.719403 | D16: ='SOC 2 HD'!F17 -> 49.082693 | E16: ='SOC 2 ES'!K15 -> 7.2421669 | F16: ='SOC 2 GUA'!H21 -> 8.6476844 | G16: ='SOC 2 PAN'!J22 -> 30.30085 | H16: =AVERAGE(B16:G16) -> 23.297733

Sheet SOC 2 CR
A6: 2024 | G6: 2023 | M6: 2022 | S6: 2021 | Y6: 2020
A7: Quintil | B7: ingreso promedio Total | D7: Ingreso promedio (Salario y cuenta autonoma) | E7: Ingreso anual | G7: Quintil | H7: ingreso promedio Total | J7: Ingreso promedio (Salario y cuenta autonoma) | K7: Ingreso anual | M7: Quintil | N7: ingreso promedio Total | P7: Ingreso promedio (Salario y cuenta autonoma) | Q7: Ingreso anual | S7: Quintil | T7: ingreso promedio Total | V7: Ingreso promedio (Salario y cuenta autonoma) | W7: Ingreso anual | Y7: Quintil | Z7: ingreso promedio Total | AB7: Ingreso promedio (Salario y cuenta autonoma) | AC7: Ingreso anual
A8: Quintil I | B8: 258789 | C8: 0.56 | D8: =C8*B8 -> 144921.84 | E8: =D8*12 -> 1739062.1 | G8: Quintil I | H8: 225198 | I8: 0.538 | J8: =I8*H8 -> 121156.52 | K8: =J8*12 -> 1453878.3 | M8: Quintil I | N8: 218126 | O8: 0.549 | P8: =O8*N8 -> 119751.17 | Q8: =P8*12 -> 1437014.1 | S8: Quintil I | T8: 203037 | U8: 0.554 | V8: =U8*T8 -> 112482.5 | W8: =V8*12 -> 1349790 | Y8: Quintil I | Z8: 200315 | AA8: 0.45 | AB8: =AA8*Z8 -> 90141.75 | AC8: =AB8*12 -> 1081701
A9: Quintil II | B9: 522563 | C9: 0.76 | D9: =C9*B9 -> 397147.88 | E9: =D9*12 -> 4765774.6 | G9: Quintil II | H9: 480175 | I9: 0.765 | J9: =I9*H9 -> 367333.88 | K9: =J9*12 -> 4408006.5 | M9: Quintil II | N9: 466200 | O9: 0.76 | P9: =O9*N9 -> 354312 | Q9: =P9*12 -> 4251744 | S9: Quintil II | T9: 433789 | U9: 0.74 | V9: =U9*T9 -> 321003.86 | W9: =V9*12 -> 3852046.3 | Y9: Quintil II | Z9: 381426 | AA9: 0.611 | AB9: =AA9*Z9 -> 233051.29 | AC9: =AB9*12 -> 2796615.4
A10: Quintil III | B10: 834691 | C10: 0.82 | D10: =C10*B10 -> 684446.62 | E10: =D10*12 -> 8213359.4 | G10: Quintil III | H10: 776767 | I10: 0.82 | J10: =I10*H10 -> 636948.94 | K10: =J10*12 -> 7643387.3 | M10: Quintil III | N10: 757091 | O10: 0.832 | P10: =O10*N10 -> 629899.71 | Q10: =P10*12 -> 7558796.5 | S10: Quintil III | T10: 709442 | U10: 0.83 | V10: =U10*T10 -> 588836.86 | W10: =V10*12 -> 7066042.3 | Y10: Quintil III | Z10: 601068 | AA10: 0.743 | AB10: =AA10*Z10 -> 446593.52 | AC10: =AB10*12 -> 5359122.3
A11: Quintil IV | B11: 1292967 | C11: 0.82 | D11: =C11*B11 -> 1060232.9 | E11: =D11*12 -> 12722795 | G11: Quintil IV | H11: 1173522 | I11: 0.837 | J11: =I11*H11 -> 982237.91 | K11: =J11*12 -> 11786855 | M11: Quintil IV | N11: 1162062 | O11: 0.828 | P11: =O11*N11 -> 962187.34 | Q11: =P11*12 -> 11546248 | S11: Quintil IV | T11: 1079538 | U11: 0.83 | V11: =U11*T11 -> 896016.54 | W11: =V11*12 -> 10752198 | Y11: Quintil IV | Z11: 998549 | AA11: 0.796 | AB11: =AA11*Z11 -> 794845 | AC11: =AB11*12 -> 9538140
A12: Quintil V | B12: 2692352 | C12: 0.8 | D12: =C12*B12 -> 2153881.6 | E12: =D12*12 -> 25846579 | G12: Quintil V | H12: 2593903 | I12: 0.804 | J12: =I12*H12 -> 2085498 | K12: =J12*12 -> 25025976 | M12: Quintil V | N12: 2515509 | O12: 0.79 | P12: =O12*N12 -> 1987252.1 | Q12: =P12*12 -> 23847025 | S12: Quintil V | T12: 2538758 | U12: 0.776 | V12: =U12*T12 -> 1970076.2 | W12: =V12*12 -> 23640914 | Y12: Quintil V | Z12: 2278895 | AA12: 0.78 | AB12: =AA12*Z12 -> 1777538.1 | AC12: =AB12*12 -> 21330457
A13: Promedio NP | D13: =AVERAGE(D9:D12) -> 1073927.3 | E13: =D13*12 -> 12887127 | G13: Promedio NP | J13: =AVERAGE(J9:J12) -> 1018004.7 | K13: =J13*12 -> 12216056 | M13: Promedio NP | P13: =AVERAGE(P9:P12) -> 983412.79 | Q13: =P13*12 -> 11800953 | S13: Promedio NP | V13: =AVERAGE(V9:V12) -> 943983.37 | W13: =V13*12 -> 11327800 | Y13: Promedio NP | AB13: =AVERAGE(AB9:AB12) -> 813006.98 | AC13: =AB13*12 -> 9756083.7
A20: año | B20: Cargo medio | C20: Salario anual NP | D20: Salario anual 20+ P | E20: % Destinado al pago de electricidad NP | F20: % Destinado al pago de electricidad 20+ P
A21: 2024 | B21: 242973 | C21: =E13 -> 12887127 | D21: =E8 -> 1739062.1 | E21: =(B21/C21)*100 -> 1.8853931 | F21: =(B21/D21)*100 -> 13.971497
A22: 2023 | B22: 223103 | C22: =K13 -> 12216056 | D22: =K8 -> 1453878.3 | E22: =(B22/C22)*100 -> 1.8263095 | F22: =(B22/D22)*100 -> 15.34537
A23: 2022 | B23: 212998 | C23: =Q13 -> 11800953 | D23: =Q8 -> 1437014.1 | E23: =(B23/C23)*100 -> 1.804922 | F23: =(B23/D23)*100 -> 14.822262
A24: 2021 | B24: 212579 | C24: =W13 -> 11327800 | D24: =W8 -> 1349790 | E24: =(B24/C24)*100 -> 1.8766132 | F24: =(B24/D24)*100 -> 15.749043
A25: 2020 | B25: =_xlfn.FORECAST.LINEAR(A25,B26:B27,A26:A27) -> 234939 | C25: =AC13 -> 9756083.7 | D25: =AC8 -> 1081701 | E25: =(B25/C25)*100 -> 2.4081282 | F25: =(B25/D25)*100 -> 21.719403
A26: 2019 | B26: 226462
A27: 2018 | B27: 217985
C29: =C21/D21 -> 7.4103894

Sheet SOC 2 HD
A1: 2022 | G1: 2023 | M1: 2024
A2: Quintil | B2: Ingreso por hogar | C2: porcentaje (en miles) del salario y cuenta autonoma | D2: Salario y cuenta autonoma | E2: Ingreso Anual | G2: Quintil | H2: Ingreso por hogar | I2: porcentaje (en miles) del salario y cuenta autonoma | J2: Salario y cuenta autonoma | K2: Ingreso Anual | M2: Quintil | N2: Ingreso por hogar | O2: porcentaje (en miles) del salario y cuenta autonoma | P2: Salario y cuenta autonoma | Q2: Ingreso Anual
A3: Quintil 1 | B3: 1776.9355 | C3: 0.66457149 | D3: =C3*B3 -> 1180.9007 | E3: =D3*12 -> 14170.808 | G3: Quintil 1 | H3: 2496.5287 | I3: 0.47960351 | J3: =I3*H3 -> 1197.3439 | K3: =J3*12 -> 14368.127 | M3: Quintil 1 | N3: 2471.5048 | O3: 0.48061484 | P3: =O3*N3 -> 1187.8419 | Q3: =P3*12 -> 14254.103
A4: Quintil 2 | B4: 5274.4287 | C4: 0.74795966 | D4: =C4*B4 -> 3945.0599 | E4: =D4*12 -> 47340.719 | G4: Quintil 2 | H4: 6554.2208 | I4: 0.60494973 | J4: =I4*H4 -> 3964.9741 | K4: =J4*12 -> 47579.69 | M4: Quintil 2 | N4: 6772.6264 | O4: 0.6406625 | P4: =O4*N4 -> 4338.9678 | Q4: =P4*12 -> 52067.613
A5: Quintil 3 | B5: 9852.8537 | C5: 0.81654671 | D5: =C5*B5 -> 8045.3153 | E5: =D5*12 -> 96543.783 | G5: Quintil 3 | H5: 10813.996 | I5: 0.68421783 | J5: =I5*H5 -> 7399.129 | K5: =J5*12 -> 88789.548 | M5: Quintil 3 | N5: 11749.663 | O5: 0.7284818 | P5: =O5*N5 -> 8559.4155 | Q5: =P5*12 -> 102712.99
A6: Quintil 4 | B6: 15465.68 | C6: 0.85288701 | D6: =C6*B6 -> 13190.478 | E6: =D6*12 -> 158285.73 | G6: Quintil 4 | H6: 16317.281 | I6: 0.74440124 | J6: =I6*H6 -> 12146.604 | K6: =J6*12 -> 145759.25 | M6: Quintil 4 | N6: 17845.235 | O6: 0.75663032 | P6: =O6*N6 -> 13502.246 | Q6: =P6*12 -> 162026.95
A7: Quintil 5 | B7: 28644.645 | C7: 0.85080075 | D7: =C7*B7 -> 24370.886 | E7: =D7*12 -> 292450.63 | G7: Quintil 5 | H7: 34291.706 | I7: 0.7751999 | J7: =I7*H7 -> 26582.927 | K7: =J7*12 -> 318995.12 | M7: Quintil 5 | N7: 34641.913 | O7: 0.77640817 | P7: =O7*N7 -> 26896.264 | Q7: =P7*12 -> 322755.17
A8: Promedio NP | D8: =AVERAGE(D4:D7) -> 12387.935 | E8: =D8*12 -> 148655.22 | G8: Promedio NP | J8: =AVERAGE(J4:J7) -> 12523.409 | K8: =J8*12 -> 150280.9 | M8: Promedio NP | P8: =AVERAGE(P4:P7) -> 13324.223 | Q8: =P8*12 -> 159890.68
D10: =D7/D3 -> 20.637541
A12: año | B12: Cargo medio | C12: Salario anual NP | D12: Salario anual 20+ P | E12: % Destinado al pago de electricidad NP | F12: % Destinado al pago de electricidad 20+ P
A13: 2024 | B13: 10476 | C13: =Q8 -> 159890.68 | D13: =Q3 -> 14254.103 | E13: =(B13/C13)*100 -> 6.5519766 | F13: =(B13/D13)*100 -> 73.49463
A14: 2023 | B14: =_xlfn.FORECAST.LINEAR(A14,B15:B17,A15:A17) -> 9464.3333 | C14: =K8 -> 150280.9 | D14: =K3 -> 14368.127 | E14: =(B14/C14)*100 -> 6.2977619 | F14: =(B14/D14)*100 -> 65.870335
A15: 2022 | B15: 8748 | C15: =E8 -> 148655.22 | D15: =E3 -> 14170.808 | E15: =(B15/C15)*100 -> 5.8847582 | F15: =(B15/D15)*100 -> 61.732542
A16: 2021 | B16: 7281 | C16: =_xlfn.FORECAST.LINEAR(A16,C13:C15,A13:A15) -> 141706.8 | D16: =_xlfn.FORECAST.LINEAR(A16,D13:D15,A13:A15) -> 14181.051 | E16: =(B16/C16)*100 -> 5.1380738 | F16: =(B16/D16)*100 -> 51.343162
A17: 2020 | B17: 6940 | C17: =_xlfn.FORECAST.LINEAR(A17,C13:C16,A13:A16) -> 136089.07 | D17: =_xlfn.FORECAST.LINEAR(A17,D13:D16,A13:A16) -> 14139.404 | E17: =(B17/C17)*100 -> 5.0996013 | F17: =(B17/D17)*100 -> 49.082693
C19: =C13/D13 -> 11.217169

Sheet SOC 2 ES
A2: Año | B2: Q1_Total | C2: Q2_Total | D2: Q3_Total | E2: Q4_Total | F2: Q5_Total | G2: Promedio NP | H2: Promedio NP anual | I2: Q1 Anual
A3: 2020 | B3: =_xlfn.FORECAST.LINEAR(A3,B4:B7,A4:A7) -> 234.915 | C3: =_xlfn.FORECAST.LINEAR(A3,C4:C7,A4:A7) -> 419.715 | D3: =_xlfn.FORECAST.LINEAR(A3,D4:D7,A4:A7) -> 583.77 | E3: =_xlfn.FORECAST.LINEAR(A3,E4:E7,A4:A7) -> 807.06 | F3: =_xlfn.FORECAST.LINEAR(A3,F4:F7,A4:A7) -> 1487.64 | G3: =AVERAGE(C3:F3) -> 824.54625 | H3: =G3*12 -> 9894.555 | I3: =B3*12 -> 2818.98
A4: 2021 | B4: =81.25*3 -> 243.75 | C4: =147.7*3 -> 443.1 | D4: =208.23*3 -> 624.69 | E4: =291.24*3 -> 873.72 | F4: =561.62*3 -> 1684.86 | G4: =AVERAGE(C4:F4) -> 906.5925 | H4: =G4*12 -> 10879.11 | I4: =B4*12 -> 2925
A5: 2022 | B5: =86.14*3 -> 258.42 | C5: =159.65*3 -> 478.95 | D5: =224.06*3 -> 672.18 | E5: =316.1*3 -> 948.3 | F5: =595.04*3 -> 1785.12 | G5: =AVERAGE(C5:F5) -> 971.1375 | H5: =G5*12 -> 11653.65 | I5: =B5*12 -> 3101.04
A6: 2023 | B6: =92.5*3 -> 277.5 | C6: =171.79*3 -> 515.37 | D6: =248.72*3 -> 746.16 | E6: =357.01*3 -> 1071.03 | F6: =702.36*3 -> 2107.08 | G6: =AVERAGE(C6:F6) -> 1109.91 | H6: =G6*12 -> 13318.92 | I6: =B6*12 -> 3330
A7: 2024 | B7: =92.03*3 -> 276.09 | C7: =175.24*3 -> 525.72 | D7: =251.34*3 -> 754.02 | E7: =360.54*3 -> 1081.62 | F7: =726.52*3 -> 2179.56 | G7: =AVERAGE(C7:F7) -> 1135.23 | H7: =G7*12 -> 13622.76 | I7: =B7*12 -> 3313.08
B10: Año | C10: Ventas (KWH) | D10: Precio (Dolares/KWh) | E10: Ingresos | F10: Clientes | G10: Cargo medio | H10: Promedio NP anual | I10: Q1 Anual | J10: % destinado NP | K10: % destinado Q1
B11: 2024 | C11: 2661740000 | D11: 0.1765901 | E11: =D11*C11 -> 4.7003693e+08 | F11: 1961053 | G11: =E11/F11 -> 239.68599 | H11: =H7 -> 13622.76 | I11: =I7 -> 3313.08 | J11: =(G11/H11)*100 -> 1.7594525 | K11: =(G11/I11)*100 -> 7.2345368
B12: 2023 | C12: 2469820000 | D12: 0.1781463 | E12: =D12*C12 -> 4.3998929e+08 | F12: 1910891 | G12: =E12/F12 -> 230.25348 | H12: =H6 -> 13318.92 | I12: =I6 -> 3330 | J12: =(G12/H12)*100 -> 1.7287699 | K12: =(G12/I12)*100 -> 6.9145188
B13: 2022 | C13: 2254700000 | D13: 0.1797162 | E13: =D13*C13 -> 4.0520612e+08 | F13: 1864350 | G13: =E13/F13 -> 217.34445 | H13: =H5 -> 11653.65 | I13: =I5 -> 3101.04 | J13: =(G13/H13)*100 -> 1.8650332 | K13: =(G13/I13)*100 -> 7.0087598
B14: 2021 | C14: 2214030000 | D14: 0.1813 | E14: =C14*D14 -> 401403639 | F14: 1816530 | G14: =E14/F14 -> 220.97276 | H14: =H4 -> 10879.11 | I14: =I4 -> 2925 | J14: =(G14/H14)*100 -> 2.0311657 | K14: =(G14/I14)*100 -> 7.5546241
B15: 2020 | C15: 2090310000 | D15: 0.1721 | E15: =C15*D15 -> 359742351 | F15: 1762102 | G15: =E15/F15 -> 204.15524 | H15: =H3 -> 9894.555 | I15: =I3 -> 2818.98 | J15: =(G15/H15)*100 -> 2.0633089 | K15: =(G15/I15)*100 -> 7.2421669
B16: 2019 | C16: 1975540000 | D16: 0.2035 | E16: =C16*D16 -> 402022390 | F16: 1723155 | G16: =E16/F16 -> 233.30599
B17: 2018 | C17: 1915540000 | D17: 0.1897 | E17: =D17*C17 -> 363377938 | F17: 1684069 | G17: =E17/F17 -> 215.77378
D21: =H11/I11 -> 4.1118114

Sheet SOC 2 GUA
A1: 2022-2023 | D1: 2022-2023
A2: Deciles | B2: Ingreso corriente total mensual | D2: Quintiles | E2: Ingreso corriente total mensual | F2: Ingreso corriente por diversos tipos de trabajo | H2: año | I2: Inflación % | J2: I | K2: II | L2: III | M2: IV | N2: V | O2: Ingreso prom NP | P2: Ingreso anual Np | Q2: Ingreso anual 20+P
A3: I | B3: 1737.5 | D3: I | E3: =(B3+B4)/2 -> 2233.45 | F3: =(E3*73.7)/100 -> 1646.0526 | H3: 2024 | I3: 1.7 | J3: =J4*(1+($I$3/100)) -> 1674.0355 | K3: =K4*(1+($I$3/100)) -> 2846.4863 | L3: =L4*(1+($I$3/100)) -> 3976.6261 | M3: =M4*(1+($I$3/100)) -> 5781.8292 | N3: =N4*(1+($I$3/100)) -> 12104.369 | O3: =AVERAGE(K3:N3) -> 6177.3276 | P3: =O3*12 -> 74127.931 | Q3: =J3*12 -> 20088.427
A4: II | B4: 2729.4 | D4: II | E4: =(B5+B6)/2 -> 3797.7 | F4: =(E4*73.7)/100 -> 2798.9049 | H4: 2023 | I4: 4.18 | J4: =F3 -> 1646.0526 | K4: =F4 -> 2798.9049 | L4: =F5 -> 3910.1535 | M4: =F6 -> 5685.1812 | N4: =F7 -> 11902.034 | O4: =AVERAGE(K4:N4) -> 6074.0684 | P4: =O4*12 -> 72888.821 | Q4: =J4*12 -> 19752.632
A5: III | B5: 3458.6 | D5: III | E5: =(B7+B8)/2 -> 5305.5 | F5: =(E5*73.7)/100 -> 3910.1535 | H5: 2022 | I5: 9.24 | J5: =J4/(1+($I$4/100)) -> 1580.0083 | K5: =K4/(1+($I$4/100)) -> 2686.6048 | L5: =L4/(1+($I$4/100)) -> 3753.2669 | M5: =M4/(1+($I$4/100)) -> 5457.0754 | N5: =N4/(1+($I$4/100)) -> 11424.49 | O5: =AVERAGE(K5:N5) -> 5830.3594 | P5: =O5*12 -> 69964.313 | Q5: =J5*12 -> 18960.1
A6: IV | B6: 4136.8 | D6: IV | E6: =(B9+B10)/2 -> 7713.95 | F6: =(E6*73.7)/100 -> 5685.1812 | H6: 2021 | I6: 3.07 | J6: =J5/(1+($I$5/100)) -> 1446.3642 | K6: =K5/(1+($I$5/100)) -> 2459.36 | L6: =L5/(1+($I$5/100)) -> 3435.7991 | M6: =M5/(1+($I$5/100)) -> 4995.4919 | N6: =N5/(1+($I$5/100)) -> 10458.157 | O6: =AVERAGE(K6:N6) -> 5337.2019 | P6: =O6*12 -> 64046.423 | Q6: =J6*12 -> 17356.371
A7: V | B7: 4863.3 | D7: V | E7: =(B11+B12)/2 -> 16149.3 | F7: =(E7*73.7)/100 -> 11902.034 | H7: 2020 | I7: 4.82 | J7: =J6/(1+($I$6/100)) -> 1403.2834 | K7: =K6/(1+($I$6/100)) -> 2386.1065 | L7: =L6/(1+($I$6/100)) -> 3333.4618 | M7: =M6/(1+($I$6/100)) -> 4846.6983 | N7: =N6/(1+($I$6/100)) -> 10146.654 | O7: =AVERAGE(K7:N7) -> 5178.2303 | P7: =O7*12 -> 62138.763 | Q7: =J7*12 -> 16839.401
A8: VI | B8: 5747.7 | H8: 2019 | J8: =J7/(1+($I$7/100)) -> 1338.7554 | K8: =K7/(1+($I$7/100)) -> 2276.3847 | L8: =L7/(1+($I$7/100)) -> 3180.1773 | M8: =M7/(1+($I$7/100)) -> 4623.8297 | N8: =N7/(1+($I$7/100)) -> 9680.0748 | O8: =O7/(1+($I$7/100)) -> 4940.1166 | P8: =P7/(1+($I$7/100)) -> 59281.4 | Q8: =Q7/(1+($I$7/100)) -> 16065.065
A9: VII | B9: 6899.3
A10: VIII | B10: 8528.6
A11: IX | B11: 11109.2
A12: X | B12: 21189.4
A16: año | B16: Ingresos social | C16: clientes social | D16: Cargo medio | E16: Ingreso anual Np | F16: Ingreso Anual 20+P | G16: % Destinado al pago de electricidad NP | H16: % Destinado al pago de electricidad NP
A17: 2024 | B17: =6791669*1000 -> 6791669000 | C17: 3847200 | D17: =B17/C17 -> 1765.3538 | E17: =P3 -> 74127.931 | F17: =Q3 -> 20088.427 | G17: =(D17/E17)*100 -> 2.3814961 | H17: =(D17/F17)*100 -> 8.7879146
A18: 2023 | B18: =6547646*1000 -> 6547646000 | C18: 3794182 | D18: =B18/C18 -> 1725.7069 | E18: =P4 -> 72888.821 | F18: =Q4 -> 19752.632 | G18: =(D18/E18)*100 -> 2.3675879 | H18: =(D18/F18)*100 -> 8.7365922
A19: 2022 | B19: =6067646.4*1000 -> 6067646400 | C19: 3696152 | D19: =B19/C19 -> 1641.6117 | E19: =P5 -> 69964.313 | F19: =Q5 -> 18960.1 | G19: =(D19/E19)*100 -> 2.3463558 | H19: =(D19/F19)*100 -> 8.6582441
A20: 2021 | B20: =5393244*1000 -> 5393244000 | C20: 3530523 | D20: =B20/C20 -> 1527.6048 | E20: =P6 -> 64046.423 | F20: =Q6 -> 17356.371 | G20: =(D20/E20)*100 -> 2.3851525 | H20: =(D20/F20)*100 -> 8.8014069
A21: 2020 | B21: =_xlfn.FORECAST.LINEAR(A21,B17:B20,A17:A20) -> 5031232700 | C21: =_xlfn.FORECAST.LINEAR(A21,C17:C20,A17:A20) -> 3454999 | D21: =B21/C21 -> 1456.2183 | E21: =P7 -> 62138.763 | F21: =Q7 -> 16839.401 | G21: =(D21/E21)*100 -> 2.3434942 | H21: =(D21/F21)*100 -> 8.6476844
E24: =E17/F17 -> 3.6900815

Sheet SOC 2 PAN
A2: Año | B2: Decil 1 | C2: Decil 2 | D2: Decil 3 | E2: Decil 4 | F2: Decil 5 | G2: Decil 6 | H2: Decil 7 | I2: Decil 8 | J2: Decil 9 | K2: Decil 10
A3: 2024 | B3: 28.217001 | C3: 75.245334 | D3: 122.27366 | E3: 178.70766 | F3: 235.14167 | G3: 324.4955 | H3: 437.36351 | I3: 573.74566 | J3: 813.59013 | K3: 1914.0532
A4: 2023 | B4: 32.745066 | C4: 79.523736 | D4: 135.65814 | E4: 187.11467 | F4: 247.92694 | G4: 322.7728 | H4: 439.71945 | I4: 566.02188 | J4: 823.30455 | K4: 1843.0795
A5: 2022 | B5: 27.917401 | C5: 74.446401 | D5: 125.6283 | E5: 181.4631 | F5: 237.2979 | G5: 316.39721 | H5: 428.06679 | I5: 572.30671 | J5: 814.2575 | K5: 1875.1187
A6: 2021 | B6: 27.767601 | C6: 69.419 | D6: 106.44246 | E6: 161.97767 | F6: 212.88493 | G6: 286.93186 | H6: 407.25814 | I6: 550.72405 | J6: 809.88833 | K6: 1994.6392
B9: Año | C9: Quintil 1 | D9: Quintil 2 | E9: Quintil 3 | F9: Quintil 4 | G9: Quintil 5 | H9: Ingreso anual NP | I9: Ingreso Anual Q1
B10: 2024 | C10: =((B3+C3)/2)*3 -> 155.1935 | D10: =((D3+E3)/2)*3 -> 451.47199 | E10: =((F3+G3)/2)*3 -> 839.45576 | F10: =((H3+I3)/2)*3 -> 1516.6638 | G10: =((J3+K3)/2)*3 -> 4091.465 | H10: =(AVERAGE(D10:G10))*12 -> 20697.169 | I10: =C10*12 -> 1862.322
B11: 2023 | C11: =((B4+C4)/2)*3 -> 168.4032 | D11: =((D4+E4)/2)*3 -> 484.15921 | E11: =((F4+G4)/2)*3 -> 856.04962 | F11: =((H4+I4)/2)*3 -> 1508.612 | G11: =((J4+K4)/2)*3 -> 3999.5761 | H11: =(AVERAGE(D11:G11))*12 -> 20545.191 | I11: =C11*12 -> 2020.8384
B12: 2022 | C12: =((B5+C5)/2)*3 -> 153.5457 | D12: =((D5+E5)/2)*3 -> 460.63711 | E12: =((F5+G5)/2)*3 -> 830.54266 | F12: =((H5+I5)/2)*3 -> 1500.5602 | G12: =((J5+K5)/2)*3 -> 4034.0642 | H12: =(AVERAGE(D12:G12))*12 -> 20477.413 | I12: =C12*12 -> 1842.5484
B13: 2021 | C13: =((B6+C6)/2)*3 -> 145.7799 | D13: =((D6+E6)/2)*3 -> 402.6302 | E13: =((F6+G6)/2)*3 -> 749.72518 | F13: =((H6+I6)/2)*3 -> 1436.9733 | G13: =((J6+K6)/2)*3 -> 4206.7913 | H13: =(AVERAGE(D13:G13))*12 -> 20388.36 | I13: =C13*12 -> 1749.3588
B14: 2020 | C14: =(_xlfn.FORECAST.LINEAR(B14,C10:C13,B10:B13)) -> 144.956 | D14: =(_xlfn.FORECAST.LINEAR(B14,D10:D13,B10:B13)) -> 407.21276 | E14: =(_xlfn.FORECAST.LINEAR(B14,E10:E13,B10:B13)) -> 745.26863 | F14: =(_xlfn.FORECAST.LINEAR(B14,F10:F13,B10:B13)) -> 1428.9215 | G14: =(_xlfn.FORECAST.LINEAR(B14,G10:G13,B10:B13)) -> 4178.0909 | H14: =(AVERAGE(D14:G14))*12 -> 20278.482 | I14: =C14*12 -> 1739.472
A17: Año | B17: Ventas | C17: Clientes | D17: Precio medio | E17: Ingresos en Balboas | F17: Cargo medio | G17: Ingreso anual NP | H17: Ingreso Anual Q1 | I17: % destinado NP | J17: % destinado Q1
A18: 2024 | B18: 3682200000 | C18: 1205983 | D18: 0.189 | E18: =B18*D18 -> 695935800 | F18: =E18/C18 -> 577.06933 | G18: =H10 -> 20697.169 | H18: =I10 -> 1862.322 | I18: =(F18/G18)*100 -> 2.7881558 | J18: =(F18/H18)*100 -> 30.986549
A19: 2023 | B19: 3550320000 | C19: 1179331 | D19: 0.172 | E19: =B19*D19 -> 610655040 | F19: =E19/C19 -> 517.79784 | G19: =H11 -> 20545.191 | H19: =I11 -> 2020.8384 | I19: =(F19/G19)*100 -> 2.5202873 | J19: =(F19/H19)*100 -> 25.622921
A20: 2022 | B20: 3290930000 | C20: 1139094 | D20: 0.183 | E20: =B20*D20 -> 602240190 | F20: =E20/C20 -> 528.70105 | G20: =H12 -> 20477.413 | H20: =I12 -> 1842.5484 | I20: =(F20/G20)*100 -> 2.5818742 | J20: =(F20/H20)*100 -> 28.694011
A21: 2021 | B21: 3322630000 | C21: 1095404 | D21: 0.162 | E21: =B21*D21 -> 538266060 | F21: =E21/C21 -> 491.38588 | G21: =H13 -> 20388.36 | H21: =I13 -> 1749.3588 | I21: =(F21/G21)*100 -> 2.4101295 | J21: =(F21/H21)*100 -> 28.089485
A22: 2020 | B22: =_xlfn.FORECAST.LINEAR(A22,B18:B21,A18:A21) -> 3126995000 | C22: =_xlfn.FORECAST.LINEAR(A22,C18:C21,A18:A21) -> 1061959.5 | D22: 0.179 | E22: =B22*D22 -> 559732105 | F22: =E22/C22 -> 527.07481 | G22: =H14 -> 20278.482 | H22: =I14 -> 1739.472 | I22: =(F22/G22)*100 -> 2.5991828 | J22: =(F22/H22)*100 -> 30.30085
E25: =G18/H18 -> 11.113636

Sheet SOC 3
A2: 2024 | K2: País | L2: Año | M2: Gen. Hidroeléctrica (GWh) | N2: Gen. Geotérmica (GWh) | O2: Gen. Eólica (GWh) | P2: Gen. Solar (GWh) | Q2: Gen. Biomasa (GWh) | R2: SUMA RENOVABLE (GWh) | S2: Gen. Térmica Fósil (GWh) | T2: GEN TOTAL (GWh) | U2: % DE EN. RENOVABLE | V2: % DE ELECTRIFICACION RURAL | W2: % ELECTRIFICACION URBANA | X2: % de hogares con acceso a energia renovable rural | Y2: % de hogares con acceso a energia renovable urbana
A3: Descripción | B3: Unidad | C3: Costa Rica | D3: El Salvador | E3: Guatemala | F3: Honduras | G3: Nicaragua | H3: Panamá | K3: Costa Rica | L3: 2020 | M3: 8294.3198 | N3: 1689.1735 | O3: 1459.4421 | P3: 9.0043 | Q3: 58.5702 | R3: =SUM(M3:Q3) -> 11510.51 | S3: 23.7307 | T3: =SUM(R3:S3) -> 11534.241 | U3: =R3/T3*100 -> 99.794259 | V3: =C53 -> 99.8 | W3: =C54 -> 99.87 | X3: =(U3*V3)/100 -> 99.59467 | Y3: =(U3*W3)/100 -> 99.664526
A4: Tasa de electrificación total | B4: % | C4: 99.4 | D4: 98.3 | E4: 90.89 | F4: 86.36 | G4: 99.56 | H4: 96 | K4: Costa Rica | L4: 2021 | M4: 9285.7142 | N4: 1601.7292 | O4: 1573.2996 | P4: 9.1637 | Q4: 67.3138 | R4: =SUM(M4:Q4) -> 12537.22 | S4: 2.8597 | T4: =SUM(R4:S4) -> 12540.08 | U4: =R4/T4*100 -> 99.977196 | V4: =C41 -> 99.8 | W4: =C42 -> 99.87 | X4: =(U4*V4)/100 -> 99.777241 | Y4: =(U4*W4)/100 -> 99.847225
A5: Rural | B5: % | C5: 99.4 | D5: 96.6 | E5: 84.95 | F5: 76.66 | G5: 72.94 | H5: 97.5 | K5: Costa Rica | L5: 2022 | M5: 9448.7087 | N5: 1618.691 | O5: 1369.2318 | P5: 8.0357 | Q5: 55.5145 | R5: =SUM(M5:Q5) -> 12500.182 | S5: 92.1153 | T5: =SUM(R5:S5) -> 12592.297 | U5: =R5/T5*100 -> 99.268479 | V5: =C29 -> 98.49 | W5: =C30 -> 99.83 | X5: =(U5*V5)/100 -> 97.769525 | Y5: =(U5*W5)/100 -> 99.099723
A6: Urbana | B6: % | C6: 99.4 | D6: 99.4 | E6: 97.4 | F6: 94 | G6: 100 | H6: 99.9 | K6: Costa Rica | L6: 2023 | M6: 8327.0235 | N6: 1479.2516 | O6: 1461.2477 | P6: 8.95099 | Q6: 55.178289 | R6: =SUM(M6:Q6) -> 11331.652 | S6: 608.06672 | T6: =SUM(R6:S6) -> 11939.719 | U6: =R6/T6*100 -> 94.907194 | V6: =C17 -> 99.4 | W6: =C18 -> 99.4 | X6: =(U6*V6)/100 -> 94.337751 | Y6: =(U6*W6)/100 -> 94.337751
K7: Costa Rica | L7: 2024 | M7: 8412.3291 | N7: 1498.0965 | O7: 1239.4692 | P7: 25.83616 | Q7: 59.906097 | R7: =SUM(M7:Q7) -> 11235.637 | S7: 1331.0305 | T7: =SUM(R7:S7) -> 12566.667 | U7: =R7/T7*100 -> 89.408246 | V7: =C5 -> 99.4 | W7: =C6 -> 99.4 | X7: =(U7*V7)/100 -> 88.871797 | Y7: =(U7*W7)/100 -> 88.871797
K8: El Salvador | L8: 2020 | M8: 2066.6015 | N8: 1449.9674 | O8: 14.083094 | P8: 898.66047 | Q8: 573.18379 | R8: =SUM(M8:Q8) -> 5002.4963 | S8: 953.58708 | T8: =SUM(R8:S8) -> 5956.0833 | U8: =R8/T8*100 -> 83.989695 | V8: =D53 -> 95.3 | W8: =D54 -> 99.3 | X8: =(U8*V8)/100 -> 80.04218 | Y8: =(U8*W8)/100 -> 83.401768
K9: El Salvador | L9: 2021 | M9: 1816.9738 | N9: 1451.6016 | O9: 131.78489 | P9: 1073.1993 | Q9: 646.39478 | R9: =SUM(M9:Q9) -> 5119.9543 | S9: 960.48057 | T9: =SUM(R9:S9) -> 6080.4349 | U9: =R9/T9*100 -> 84.203752 | V9: =D41 -> 95.6 | W9: =D42 -> 99.2 | X9: =(U9*V9)/100 -> 80.498787 | Y9: =(U9*W9)/100 -> 83.530122
K10: El Salvador | L10: 2022 | M10: 2234.1286 | N10: 1468.0004 | O10: 134.89596 | P10: 1109.2178 | Q10: 574.38391 | R10: =SUM(M10:Q10) -> 5520.6267 | S10: 1613.2709 | T10: =SUM(R10:S10) -> 7133.8977 | U10: =R10/T10*100 -> 77.385841 | V10: =D29 -> 96.4 | W10: =D30 -> 99.3 | X10: =(U10*V10)/100 -> 74.599951 | Y10: =(U10*W10)/100 -> 76.84414
K11: El Salvador | L11: 2023 | M11: 1568.3034 | N11: 1478.3824 | O11: 166.80886 | P11: 1194.1039 | Q11: 554.93683 | R11: =SUM(M11:Q11) -> 4962.5353 | S11: 3192.4814 | T11: =SUM(R11:S11) -> 8155.0168 | U11: =R11/T11*100 -> 60.852546 | V11: =D17 -> 96.6 | W11: =D18 -> 99.4 | X11: =(U11*V11)/100 -> 58.783559 | Y11: =(U11*W11)/100 -> 60.487431
K12: El Salvador | L12: 2024 | M12: 2199.3477 | N12: 1481.0652 | O12: 145.78107 | P12: 1259.9624 | Q12: 563.27716 | R12: =SUM(M12:Q12) -> 5649.4335 | S12: 2545.6672 | T12: =SUM(R12:S12) -> 8195.1007 | U12: =R12/T12*100 -> 68.936718 | V12: =D5 -> 96.6 | W12: =E6 -> 97.4 | X12: =(U12*V12)/100 -> 66.59287 | Y12: =(U12*W12)/100 -> 67.144364
K13: Guatemala | L13: 2020 | M13: 5816.5379 | N13: 273.85603 | O13: 312.68393 | P13: 221.50676 | Q13: 1747.9294 | R13: =SUM(M13:Q13) -> 8372.514 | S13: 2749.5483 | T13: =SUM(R13:S13) -> 11122.062 | U13: =R13/T13*100 -> 75.278431 | V13: =E53 -> 81.3 | W13: =E54 -> 96.2 | X13: =(U13*V13)/100 -> 61.201364 | Y13: =(U13*W13)/100 -> 72.417851
A14: 2023 | K14: Guatemala | L14: 2021 | M14: 5960.293 | N14: 264.96828 | O14: 323.79532 | P14: 229.6003 | Q14: 1745.1177 | R14: =SUM(M14:Q14) -> 8523.7746 | S14: 3419.3026 | T14: =SUM(R14:S14) -> 11943.077 | U14: =R14/T14*100 -> 71.370003 | V14: =E41 -> 84.2 | W14: =E42 -> 97.1 | X14: =(U14*V14)/100 -> 60.093543 | Y14: =(U14*W14)/100 -> 69.300273
A15: Descripción | B15: Unidad | C15: Costa Rica | D15: El Salvador | E15: Guatemala | F15: Honduras | G15: Nicaragua | H15: Panamá | K15: Guatemala | L15: 2022 | M15: 6942.2191 | N15: 281.9886 | O15: 313.79509 | P15: 219.86656 | Q15: 1658.7549 | R15: =SUM(M15:Q15) -> 9416.6242 | S15: 2608.0842 | T15: =SUM(R15:S15) -> 12024.708 | U15: =R15/T15*100 -> 78.310624 | V15: =E29 -> 83.1 | W15: =E30 -> 96.9 | X15: =(U15*V15)/100 -> 65.076129 | Y15: =(U15*W15)/100 -> 75.882995
A16: Tasa de electrificación total | B16: % | C16: 99.4 | D16: 98.3 | E16: 90.39 | F16: 86.28 | G16: 99.41 | H16: 95.6 | K16: Guatemala | L16: 2023 | M16: 5571.8793 | N16: 285.4383 | O16: 343.95678 | P16: 245.91834 | Q16: 1648.9676 | R16: =SUM(M16:Q16) -> 8096.1604 | S16: 4126.7294 | T16: =SUM(R16:S16) -> 12222.89 | U16: =R16/T16*100 -> 66.237694 | V16: =E17 -> 84.2 | W16: =E18 -> 97.1 | X16: =(U16*V16)/100 -> 55.772139 | Y16: =(U16*W16)/100 -> 64.316801
A17: Rural | B17: % | C17: 99.4 | D17: 96.6 | E17: 84.2 | F17: 75.92 | G17: 72.94 | H17: 93.7 | K17: Guatemala | L17: 2024 | M17: 5334.174 | N17: 275.03643 | O17: 286.43386 | P17: 252.10352 | Q17: 1611.6517 | R17: =SUM(M17:Q17) -> 7759.3995 | S17: 5358.008 | T17: =SUM(R17:S17) -> 13117.407 | U17: =R17/T17*100 -> 59.153453 | V17: =E5 -> 84.95 | W17: =E6 -> 97.4 | X17: =(U17*V17)/100 -> 50.250859 | Y17: =(U17*W17)/100 -> 57.615464
A18: Urbana | B18: % | C18: 99.4 | D18: 99.4 | E18: 97.1 | F18: 94.43 | G18: 100 | H18: 99.9 | K18: Honduras | L18: 2020 | M18: 2700.64 | N18: 306.98834 | O18: 708.88085 | P18: 1112.8126 | Q18: 789.12286 | R18: =SUM(M18:Q18) -> 5618.4446 | S18: 4447.8591 | T18: =SUM(R18:S18) -> 10066.304 | U18: =R18/T18*100 -> 55.814376 | V18: =F53 -> 69.22 | W18: =F54 -> 98.26 | X18: =(U18*V18)/100 -> 38.634711 | Y18: =(U18*W18)/100 -> 54.843206
K19: Honduras | L19: 2021 | M19: 3765.2174 | N19: 348.19706 | O19: 776.56155 | P19: 1140.4567 | Q19: 803.81546 | R19: =SUM(M19:Q19) -> 6834.2481 | S19: 4247.7951 | T19: =SUM(R19:S19) -> 11082.043 | U19: =R19/T19*100 -> 61.669567 | V19: =F41 -> 74.41 | W19: =F42 -> 94.65 | X19: =(U19*V19)/100 -> 45.888325 | Y19: =(U19*W19)/100 -> 58.370246
K20: Honduras | L20: 2022 | M20: 3882.5024 | N20: 337.18583 | O20: 686.36615 | P20: 1037.9174 | Q20: 805.40507 | R20: =SUM(M20:Q20) -> 6749.3768 | S20: 4535.7613 | T20: =SUM(R20:S20) -> 11285.138 | U20: =R20/T20*100 -> 59.807658 | V20: =F29 -> 74.47 | W20: =F30 -> 94.49 | X20: =(U20*V20)/100 -> 44.538763 | Y20: =(U20*W20)/100 -> 56.512256
K21: Honduras | L21: 2023 | M21: 3208.2357 | N21: 318.2646 | O21: 770.1372 | P21: 1094.3221 | Q21: 797.87974 | R21: =SUM(M21:Q21) -> 6188.8393 | S21: 5655.0797 | T21: =SUM(R21:S21) -> 11843.919 | U21: =R21/T21*100 -> 52.253306 | V21: =F17 -> 75.92 | W21: =F18 -> 94.43 | X21: =(U21*V21)/100 -> 39.67071 | Y21: =(U21*W21)/100 -> 49.342797
K22: Honduras | L22: 2024 | M22: 3834.2798 | N22: 304.83861 | O22: 666.59963 | P22: 1147.7852 | Q22: 691.70763 | R22: =SUM(M22:Q22) -> 6645.2109 | S22: 6049.0302 | T22: =SUM(R22:S22) -> 12694.241 | U22: =R22/T22*100 -> 52.348233 | V22: =F5 -> 76.66 | W22: =F6 -> 94 | X22: =(U22*V22)/100 -> 40.130155 | Y22: =(U22*W22)/100 -> 49.207339
K23: Nicaragua | L23: 2020 | M23: 574.47111 | N23: 767.31204 | O23: 549.93345 | P23: 25.955317 | Q23: 732.77738 | R23: =SUM(M23:Q23) -> 2650.4493 | S23: 1146.6083 | T23: =SUM(R23:S23) -> 3797.0575 | U23: =R23/T23*100 -> 69.802716 | V23: =G53 -> 72.94 | W23: =G54 -> 100 | X23: =(U23*V23)/100 -> 50.914101 | Y23: =(U23*W23)/100 -> 69.802716
K24: Nicaragua | L24: 2021 | M24: 599.02557 | N24: 734.03198 | O24: 655.8375 | P24: 27.271588 | Q24: 898.78698 | R24: =SUM(M24:Q24) -> 2914.9536 | S24: 1297.5394 | T24: =SUM(R24:S24) -> 4212.4931 | U24: =R24/T24*100 -> 69.197826 | V24: =G41 -> 72.94 | W24: =G42 -> 100 | X24: =(U24*V24)/100 -> 50.472894 | Y24: =(U24*W24)/100 -> 69.197826
K25: Nicaragua | L25: 2022 | M25: 650.15224 | N25: 687.16916 | O25: 561.87183 | P25: 26.099762 | Q25: 890.45252 | R25: =SUM(M25:Q25) -> 2815.7455 | S25: 1476.8875 | T25: =SUM(R25:S25) -> 4292.633 | U25: =R25/T25*100 -> 65.594834 | V25: =G29 -> 72.94 | W25: =G30 -> 100 | X25: =(U25*V25)/100 -> 47.844872 | Y25: =(U25*W25)/100 -> 65.594834
A26: 2022 | K26: Nicaragua | L26: 2023 | M26: 469.54198 | N26: 751.14885 | O26: 665.34423 | P26: 27.221494 | Q26: 914.55866 | R26: =SUM(M26:Q26) -> 2827.8152 | S26: 2001.6861 | T26: =SUM(R26:S26) -> 4829.5014 | U26: =R26/T26*100 -> 58.552944 | V26: =G17 -> 72.94 | W26: =G18 -> 100 | X26: =(U26*V26)/100 -> 42.708517 | Y26: =(U26*W26)/100 -> 58.552944
A27: Descripción | B27: Unidad | C27: Costa Rica | D27: El Salvador | E27: Guatemala | F27: Honduras | G27: Nicaragua | H27: Panamá | K27: Nicaragua | L27: 2024 | M27: 339.10468 | N27: 821.08546 | O27: 787.87176 | P27: 28.391437 | Q27: 939.3174 | R27: =SUM(M27:Q27) -> 2915.7707 | S27: 2712.9673 | T27: =SUM(R27:S27) -> 5628.738 | U27: =R27/T27*100 -> 51.8015 | V27: =G5 -> 72.94 | W27: =G6 -> 100 | X27: =(U27*V27)/100 -> 37.784014 | Y27: =(U27*W27)/100 -> 51.8015
A28: Tasa de electrificación total | B28: % | C28: 99.4 | D28: 98.2 | E28: 89.94 | F28: 85.63 | G28: 99.26 | H28: 95.2 | K28: Panamá | L28: 2020 | M28: 7349.2 | N28: 0 | O28: 584.2 | P28: 385 | Q28: 29.8 | R28: =SUM(M28:Q28) -> 8348.2 | S28: 4487.34 | T28: =SUM(R28:S28) -> 12835.54 | U28: =R28/T28*100 -> 65.039726 | V28: =H53 -> 83.02 | W28: =H54 -> 99.7 | X28: =(U28*V28)/100 -> 53.99598 | Y28: =(U28*W28)/100 -> 64.844606
A29: Rural | B29: % | C29: 98.49 | D29: 96.4 | E29: 83.1 | F29: 74.47 | G29: 72.94 | H29: 90.6 | K29: Panamá | L29: 2021 | M29: 8345.3 | N29: 0 | O29: 529.6 | P29: 671.5 | Q29: 47.999 | R29: =SUM(M29:Q29) -> 9594.399 | S29: 4407 | T29: =SUM(R29:S29) -> 14001.399 | U29: =R29/T29*100 -> 68.524574 | V29: =H41 -> 84.75 | W29: =H42 -> 99.78 | X29: =(U29*V29)/100 -> 58.074576 | Y29: =(U29*W29)/100 -> 68.37382
A30: Urbana | B30: % | C30: 99.83 | D30: 99.3 | E30: 96.9 | F30: 94.49 | G30: 100 | H30: 99.8 | K30: Panamá | L30: 2022 | M30: 8117.4 | N30: 0 | O30: 579.3 | P30: 703.1 | Q30: 73.2 | R30: =SUM(M30:Q30) -> 9473 | S30: 4593.55 | T30: =SUM(R30:S30) -> 14066.55 | U30: =R30/T30*100 -> 67.34416 | V30: =H29 -> 90.6 | W30: =H30 -> 99.8 | X30: =(U30*V30)/100 -> 61.013809 | Y30: =(U30*W30)/100 -> 67.209472
K31: Panamá | L31: 2023 | M31: 6140.8 | N31: 0 | O31: 891.65 | P31: 866.82 | Q31: 48.6 | R31: =SUM(M31:Q31) -> 7947.87 | S31: 6583.51 | T31: =SUM(R31:S31) -> 14531.38 | U31: =R31/T31*100 -> 54.69453 | V31: =H17 -> 93.7 | W31: =H18 -> 99.9 | X31: =(U31*V31)/100 -> 51.248775 | Y31: =(U31*W31)/100 -> 54.639836
K32: Panamá | L32: 2024 | M32: 7817.4919 | N32: 0 | O32: 667.77153 | P32: 1024.5487 | Q32: 20.146813 | R32: =SUM(M32:Q32) -> 9529.959 | S32: 3511.5255 | T32: =SUM(R32:S32) -> 13041.484 | U32: =R32/T32*100 -> 73.074189 | V32: =H5 -> 97.5 | W32: =H6 -> 99.9 | X32: =(U32*V32)/100 -> 71.247334 | Y32: =(U32*W32)/100 -> 73.001115
K33: TOTAL SIEPAC | L33: 2020 | X33: =AVERAGEIF(L3:L32, L3,X3:X32) -> 64.063834 | Y33: =AVERAGEIF(L3:L32, L3,Y3:Y32) -> 74.162445
L34: 2021 | X34: =AVERAGEIF(L3:L32,L4,X3:X32) -> 65.800894 | Y34: =AVERAGEIF(L3:L32,L4,Y3:Y32) -> 74.769919
L35: 2022 | X35: =AVERAGEIF(L3:L32,L5,X3:X32) -> 65.140508 | Y35: =AVERAGEIF(L3:L32, L5,Y3:Y32) -> 73.523903
L36: 2023 | X36: =AVERAGEIF(L3:L32,L6,X3:X32) -> 57.086908 | Y36: =AVERAGEIF(L3:L32, L6,Y3:Y32) -> 63.612927
L37: 2024 | X37: =AVERAGEIF(L3:L32,L7,X3:X32) -> 59.146172 | Y37: =AVERAGEIF(L3:L32, L7,Y3:Y32) -> 64.60693
A38: 2021
A39: Descripción | B39: Unidad | C39: Costa Rica | D39: El Salvador | E39: Guatemala | F39: Honduras | G39: Nicaragua | H39: Panamá
A40: Tasa de electrificación total | B40: % | C40: 99.4 | D40: 97.9 | E40: 89.26 | F40: 8577 | G40: 99.09 | H40: 94.9
A41: Rural | B41: % | C41: 99.8 | D41: 95.6 | E41: 84.2 | F41: 74.41 | G41: 72.94 | H41: 84.75
...

Sheet Capacidad instalada
A1: capacidaad instalada
A3: La capacidad de generación disponible en los países del MER 2024
A4: Recurso | B4: Guatemala | C4: El Salvador | D4: Honduras | E4: Nicaragua | F4: Costa Rica | G4: Panamá | H4: Total CA
A5: Hidroelectrico | B5: 1530.7 | C5: 623.2 | D5: 922.1 | E5: 139.2 | F5: 2101.8 | G5: 1778.2 | H5: =SUM(B5:G5) -> 7095.2
A6: Solar FV | B6: 80 | C6: 392.3 | D6: 504.7 | E6: 37 | F6: 21.4 | G6: 589.1 | H6: =SUM(B6:G6) -> 1624.5
A7: Eólico | B7: 102.5 | C7: 50 | D7: 238.1 | E7: 186.6 | F7: 395.8 | G7: 336 | H7: =SUM(B7:G7) -> 1309
A8: Generacion Distribuida | B8: 54.8 | H8: =SUM(B8:G8) -> 54.8
A9: Geotermico | B9: 33.6 | C9: 181.5 | D9: 35 | E9: 110 | F9: 206.7 | H9: =SUM(B9:G9) -> 566.8
A10: Biomasa | B10: 671.2 | C10: 208 | D10: 233.9 | E10: 146 | F10: 37.3 | G10: 40.1 | H10: =SUM(B10:G10) -> 1336.5
A11: Gas Natural | B11: 2.6 | C11: 378.5 | G11: 381 | H11: =SUM(B11:G11) -> 762.1
A12: Carbón | B12: 483.4 | D12: 105 | G12: 300 | H12: =SUM(B12:G12) -> 888.4
A13: Fuel oil | B13: 619.3 | C13: 708.7 | D13: 1008.7 | E13: 548.9 | F13: 310.9 | G13: 708.8 | H13: =SUM(B13:G13) -> 3905.3
A14: Total/ recurso | B14: =SUM(B5:B13) -> 3578.1 | C14: =SUM(C5:C13) -> 2542.2 | D14: =SUM(D5:D13) -> 3047.5 | E14: =SUM(E5:E13) -> 1167.7 | F14: =SUM(F5:F13) -> 3073.9 | G14: =SUM(G5:G13) -> 4133.2 | H14: =SUM(H5:H13) -> 17542.6
A15: Total renovable | B15: =SUM(B5:B10) -> 2472.8 | C15: =SUM(C5:C10) -> 1455 | D15: =SUM(D5:D10) -> 1933.8 | E15: =SUM(E5:E10) -> 618.8 | F15: =SUM(F5:F10) -> 2763 | G15: =SUM(G5:G10) -> 2743.4 | H15: =SUM(H5:H10) -> 11986.8
A16: % de energia renovable | B16: =(B15*100)/B14 -> 69.109304 | C16: =(C15*100)/C14 -> 57.233892 | D16: =(D15*100)/D14 -> 63.455291 | E16: =(E15*100)/E14 -> 52.993063 | F16: =(F15*100)/F14 -> 89.885813 | G16: =(G15*100)/G14 -> 66.374722 | H16: =(H15*100)/H14 -> 68.329666
A21: La capacidad de generación disponible en los países del MER 2023
A22: Recurso | B22: Guatemala | C22: El Salvador | D22: Honduras | E22: Nicaragua | F22: Costa Rica | G22: Panamá | H22: Total CA
A23: Hidroelectrico | B23: 1530.7 | C23: 557.2 | D23: 922.1 | E23: 139.2 | F23: 2147.4 | G23: 1776.6 | H23: =SUM(B23:G23) -> 7073.2
A24: Solar FV | B24: 80 | C24: 219 | D24: 504.7 | E24: 37 | F24: 21.4 | G24: 594.3 | H24: =SUM(B24:G24) -> 1456.4
A25: Eólico | B25: 102.5 | C25: 50 | D25: 238.1 | E25: 186.6 | F25: 402.3 | G25: 336 | H25: =SUM(B25:G25) -> 1315.5
A26: Generacion Distribuida | B26: 54.8 | H26: =SUM(B26:G26) -> 54.8
A27: Geotermico | B27: 33.6 | C27: 174.5 | D27: 35 | E27: 110 | F27: 212.7 | H27: =SUM(B27:G27) -> 565.8
A28: Biomasa | B28: 671.2 | C28: 208 | D28: 233.9 | E28: 146 | F28: 37.3 | G28: 40.1 | H28: =SUM(B28:G28) -> 1336.5
A29: Gas Natural | B29: 2.6 | C29: 378.5 | G29: 381 | H29: =SUM(B29:G29) -> 762.1
A30: Carbón | B30: 483.4 | D30: 105 | G30: 300 | H30: =SUM(B30:G30) -> 888.4
A31: Fuel oil | B31: 619.3 | C31: 708.7 | D31: 1008.7 | E31: 767.9 | F31: 310.9 | G31: 708.8 | H31: =SUM(B31:G31) -> 4124.3
A32: Total/ recurso | B32: =SUM(B23:B31) -> 3578.1 | C32: =SUM(C23:C31) -> 2295.9 | D32: =SUM(D23:D31) -> 3047.5 | E32: =SUM(E23:E31) -> 1386.7 | F32: =SUM(F23:F31) -> 3132 | G32: =SUM(G23:G31) -> 4136.8 | H32: =SUM(H23:H31) -> 17577
A33: total renovable | B33: =SUM(B23:B28) -> 2472.8 | C33: =SUM(C23:C28) -> 1208.7 | D33: =SUM(D23:D28) -> 1933.8 | E33: =SUM(E23:E28) -> 618.8 | F33: =SUM(F23:F28) -> 2821.1 | G33: =SUM(G23:G28) -> 2747 | H33: =SUM(H23:H28) -> 11802.2
A34: % de energia renovable | B34: =(B33*100)/B32 -> 69.109304 | C34: =(C33*100)/C32 -> 52.646021 | D34: =(D33*100)/D32 -> 63.455291 | E34: =(E33*100)/E32 -> 44.623927 | F34: =(F33*100)/F32 -> 90.073436 | G34: =(G33*100)/G32 -> 66.403984 | H34: =(H33*100)/H32 -> 67.145702
A39: La capacidad de generación disponible en los países del MER 2022
A40: Recurso | B40: Guatemala | C40: El Salvador | D40: Honduras | E40: Nicaragua | F40: Costa Rica | G40: Panamá | H40: Total CA
A41: Hidroelectrico | B41: 1530.7 | C41: 557.2 | D41: 925.2 | E41: 139.2 | F41: 2032.7 | G41: 1797.5 | H41: =SUM(B41:G41) -> 6982.5
A42: Solar FV | B42: 80 | C42: 219 | D42: 504.7 | E42: 12 | F42: 16.4 | G42: 380.7 | H42: =SUM(B42:G42) -> 1212.8
A43: Eólico | B43: 102.5 | C43: 50 | D43: 240.3 | E43: 186.6 | F43: 395.8 | G43: 270 | H43: =SUM(B43:G43) -> 1245.2
A44: Generacion Distribuida | B44: 43 | H44: =SUM(B44:G44) -> 43
A45: Geotermico | B45: 33.6 | C45: 174.5 | D45: 35 | E45: 110 | F45: 207.7 | H45: =SUM(B45:G45) -> 560.8
A46: Biomasa | B46: 671.2 | C46: 208 | D46: 233.9 | E46: 119 | F46: 37.3 | G46: 8.1 | H46: =SUM(B46:G46) -> 1277.5
A47: Gas Natural | B47: 2.6 | G47: 381 | H47: =SUM(B47:G47) -> 383.6
A48: Carbón | B48: 513.4 | D48: 105 | G48: 433 | H48: =SUM(B48:G48) -> 1051.4
A49: Fuel oil | B49: 676.4 | C49: 708.7 | D49: 935.5 | E49: 767.9 | F49: 353 | G49: 1148.2 | H49: =SUM(B49:G49) -> 4589.7
...

Sheet Hoja1
A1: 2021 | B1: Nacional | C1: Decil 1 | D1: 62.160002
A2: 2021 | B2: Nacional | C2: Decil 10 | D2: 4465.1598
A3: 2021 | B3: Nacional | C3: Decil 2 | D3: 155.4
A4: 2021 | B4: Nacional | C4: Decil 3 | D4: 238.28
A5: 2021 | B5: Nacional | C5: Decil 4 | D5: 362.6
A6: 2021 | B6: Nacional | C6: Decil 5 | D6: 476.55999
A7: 2021 | B7: Nacional | C7: Decil 6 | D7: 642.31998
A8: 2021 | B8: Nacional | C8: Decil 7 | D8: 911.68002
A9: 2021 | B9: Nacional | C9: Decil 8 | D9: 1232.84
A10: 2021 | B10: Nacional | C10: Decil 9 | D10: 1813
A11: 2022 | B11: Nacional | C11: Decil 1 | D11: 62.160002
A12: 2022 | B12: Nacional | C12: Decil 10 | D12: 4175.0799
... A40: 2024 | B40: Nacional | C40: Decil 9 | D40: 1792.2799
